<!DOCTYPE html>
<html lang="en">
  <head>
    <meta charset="UTF-8" />
    <meta http-equiv="X-UA-Compatible" content="IE=edge" />
    <meta name="viewport" content="width=device-width, initial-scale=1.0" />
    <title>Document</title>
  </head>
  <body>
    <script>
      const someAsyncThing = function () {
        return new Promise(function (resolve, reject) {
          // 下面一行会报错，因为x没有声明
          //浏览器运行到这一行，会打印出错误提示ReferenceError: x is not defined，但是不会退出进程、终止脚本执行
          resolve(x + 2);
        });
      };

      someAsyncThing().then(function () {
        console.log("everything is great");
      });
      //Promise 内部的错误不会影响到 Promise 外部的代码，通俗的说法就是“Promise 会吃掉错误”。
      setTimeout(() => {
        console.log(456);
      }, 2000);
      console.log(123);
      // Uncaught (in promise) ReferenceError: x is not defined
      // 123
      // 456

      //Promise 指定在下一轮“事件循环”再抛出错误。
      //到了那个时候，Promise 的运行已经结束了，所以这个错误是在 Promise 函数体外抛出的，会冒泡到最外层，成了未捕获的错误。
      const promise = new Promise(function (resolve, reject) {
        resolve("ok");
        setTimeout(function () {
          throw new Error("test");
        }, 0);
      });
      promise.then(function (value) {
        console.log(value);
      });
    </script>
  </body>
</html>
